<mujoco model="hand model">
    <visual>
        <headlight diffuse="0.6 0.6 0.6" ambient="0.3 0.3 0.3" specular="0 0 0" />
        <rgba haze="0.15 0.25 0.35 1" />
        <map znear="0.01" />
        <global offwidth="1024" offheight="1024" />
    </visual>
    <asset>
        <texture type="skybox" builtin="gradient" rgb1="1 1 1" rgb2="1 1 1" width="512" height="3072" />
        <texture type="2d" name="groundplane" builtin="checker" mark="edge" rgb1="0.2 0.3 0.4" rgb2="0.1 0.2 0.3" markrgb="0.8 0.8 0.8" width="300" height="300" />
        <material name="groundplane" texture="groundplane" texuniform="true" texrepeat="10 10" reflectance="0.3" />
        <material name="bone" reflectance="1" shininess="0" specular="0" rgba="0.68 0.64 0.57 1" />
    </asset>
    <default>
        <default class="zf">
            <geom type="mesh" contype="3" conaffinity="2" group="0" friction="0.7" solref="0.015 1" solimp="0.95 0.99 0.003" rgba="0.78 0.64 0.57 0.9" />
        </default>
        <default class="dau">
            <geom type="mesh" contype="3" conaffinity="2" group="0" friction="0.7" solref="0.015 1" solimp="0.95 0.99 0.003" rgba="0.78 0.64 0.37 0.9" />
        </default>
        <default class="base">
            <geom type="mesh" contype="3" conaffinity="2" group="0" friction="0.7" solref="0.015 1" solimp="0.95 0.99 0.003" rgba="0.74 0.60 0.47 0.1" />
        </default>
        <default class="other">
            <geom type="mesh" contype="3" conaffinity="2" group="0" friction="0.7" solref="0.015 1" solimp="0.95 0.99 0.003" rgba="0.74 0.60 0.67 0.1" />
        </default>
        <default class="visual">
            <geom type="mesh" contype="0" conaffinity="0" group="2" material="bone" rgba="0.68 0.64 0.57 1.0" />
        </default>
        <default class="tracker">
            <geom type="mesh" contype="0" conaffinity="0" group="2" rgba="0.2 0.2 1 0.2" />
        </default>
    </default>

    <compiler angle="radian" meshdir="../../assets/meshes" texturedir="assets" />
    <option integrator="RK4" />

    <statistic center="-0.4 -0.4 0.2" extent="1.2" />

    <asset>
        <mesh file="Segmentation_ZF_DIP.stl" name="ZF-DIP" scale="0.001 0.001 0.001" />
        <mesh file="Segmentation_ZF_PIP.stl" name="ZF-PIP1" scale="0.001 0.001 0.001" />
        <mesh file="zf_mid2.stl" name="ZF-PIP2" scale="0.001 0.001 0.001" />
        <mesh file="zf_mcp.stl" name="ZF-MCP" scale="0.001 0.001 0.001" />
        <mesh file="Segmentation_DAU_Osmetacarpale_1.stl" name="DAU-MCP" scale="0.001 0.001 0.001" />
        <mesh file="Segmentation_DAU_Phalax_proximalis.stl" name="DAU-PIP" scale="0.001 0.001 0.001" />
        <mesh file="Segmentation_DAU_DIP.stl" name="DAU-DIP" scale="0.001 0.001 0.001" />
        <mesh file="backhand.stl" name="BASE" scale="0.001 0.001 0.001" />
        <mesh file="rest.stl" name="OTHER" scale="0.001 0.001 0.001" />
    </asset>


    <worldbody>

        <light pos="0 0 1.5" dir="0 0 -1" directional="true" />
        


        <body name="ZF_MCP" pos="0.1776774 -0.007402596 0.16383637" quat="0.94908375 0.26175642 0.15019616 -0.096228346">

            <geom class="zf" mesh="ZF-MCP" type="mesh" />
            <geom class="base" mesh="BASE" type="mesh" />
            <geom class="other" mesh="OTHER" type="mesh" />


            <body name="DAU_MCP" pos="0.0003336841 0.0020733923 0.0021159737" quat="0.99705034 -0.0019221723 0.0048085903 -0.0048973868">
                <geom class="dau" mesh="DAU-MCP" type="mesh" />

                <joint armature="0.001" axis="0.2719148 0.8001213 -0.5346664" limited="true" name="ZF_MCP_to_DAU_CMC" pos="0.3004469 -0.10252256 -0.304348" range="-1 1" type="hinge" />
                <joint armature="0.001" axis="0.65481335 -0.6477929 -0.38933775" limited="true" name="DAU_CMC_to_DAU_MCP" pos="0.097862855 -0.30560312 -0.19511186" range="-0.2 1" type="hinge" />

                <body name="DAU_PIP" pos="0.006258016 0.0052959076 -0.00051674433" quat="0.99935913 -0.00891185 0.0006945565 -0.017817944">
                    <geom class="dau" mesh="DAU-PIP" type="mesh" />

                    <joint armature="0.001" axis="0.9999739 0.0017957857 0.0069901343" limited="true" name="DAU_MCP_to_DAU_PIP" pos="-0.0010338341 0.0015279563 -0.0027946834" range="-0.2 1" type="hinge" />

                    <body name="DAU_DIP" pos="0.017012665 0.0038345633 -0.004492165" quat="0.9958929 -0.0010636775 0.01020363 -0.040629536">
                        <geom class="dau" mesh="DAU-DIP" type="mesh" />

                        <joint armature="0.001" axis="0.9999561 -0.008747879 0.0033733502" limited="true" name="DAU_PIP_to_DAU_DIP" pos="0.01364396 -0.003849878 0.0051481607" range="-0.2 1" type="hinge" />
                        <body name="DAU_TIP" pos="-0.0022919488 0.0021974177 -0.001919363" quat="0.9988924 -0.0027410362 -0.0015700125 -0.0046329987" />
                    </body>
                </body>
            </body>


            <body name="ZF_PIP2" pos="-0.054679856 0.04752336 -0.119985886" quat="0.95702666 -0.22162813 -0.19403175 0.032083143">
                <geom class="zf" mesh="ZF-PIP2" type="mesh" />

                <joint armature="0.001" axis="0.99999255 -0.0009669341 0.00371579" limited="true" name="ZF_MCP_to_ZF_PIP2" pos="0.006527642 0.0041843415 -0.0038207527" range="-0.4 1" type="hinge" />

                <body name="ZF_PIP1" pos="0.0038876198 -0.02574792 0.039141763" quat="0.9988716 0.09147741 0.0335273 0.018810697">
                    <geom class="zf" mesh="ZF-PIP1" type="mesh" />

                    <joint armature="0.001" axis="0.9999932 0.0036120713 0.00067524385" limited="true" name="ZF_PIP2_to_ZF_PIP1" pos="0.0111344 0.0037476083 -0.0065740296" range="-0.4 1" type="hinge" />

                    <body name="ZF_DIP" pos="-0.007816592 -0.01059114 0.018520506" quat="1.0035625 0.044750743 -0.0014234553 0.019875223">
                        <geom class="zf" mesh="ZF-DIP" type="mesh" />

                        <joint armature="0.001" axis="0.99992114 0.009776571 -0.007879023" limited="true" name="ZF_PIP1_to_ZF_DIP" pos="-0.0047561983 0.00058624975 -0.0059370934" range="-0.4 1" type="hinge" />

                        <body name="ZF_TIP" pos="0.004804371 0.0044412194 -7.857382e-05" quat="1.0016588 -0.004690258 -0.0015940046 0.0024381964" />
                    </body>
                </body>
            </body>
        </body>

        <camera name="camera0" pos="1.310 0.211 -0.200" xyaxes="-0.256 0.967 0.000 0.111 0.029 0.993" />

    </worldbody>
</mujoco>